Workbook
Name IQ_CH: 110000
Name IQ_CQ: 5000
Name IQ_CY: 10000
Name IQ_DAILY: 500000
Name IQ_FH: 100000
Name IQ_FQ: 500
Name IQ_FY: 1000
Name IQ_LTM: 2000
Name IQ_MONTH: 15000
Name IQ_NTM: 6000
Name IQ_WEEK: 50000
Name IQ_YTD: 3000

Sheet Cover Sheet>
G23: 3 Statement Model DCF Valuation Relative Valuation

Sheet Input Sheet
B4: Please Provide the Below Inputs | L4: L | M4: Y
L5: S | M5: N
B6: Name of the Company | C6: Hindustan Unilever Ltd.
B8: WACC Inputs
B9: Country | C9: India
B10: Local Currency 10Y Government Bond Yield | C10: 0.06679
B11: =C9&"'s"&" Moody's Sovereign Rating" -> India's Moody's Sovereign Rating | C11: =VLOOKUP(C9,'Damodaran Data'!B4:C160,2,FALSE) -> Baa3
B12: =C9&"'s"&" Credit Default Spread as per Dr Damodaran" -> India's Credit Default Spread as per Dr Damodaran | C12: =VLOOKUP(C9,'Damodaran Data'!B4:D160,3,FALSE) -> 0.0187
B13: Implied US Equity Risk Premium | C13: 0.0438
B14: Asset Beta | C14: 0.68
B15: Asset Beta Variation (+/-) | C15: 0.01
B16: Debt to Equity Ratio | C16: ='Assumptions Working'!J1155 -> 0.033205822
B17: Debt to Capital (Gearing) | C17: ='Assumptions Working'!J1156 -> 0.032138199
B18: Marginal Tax Rate | C18: 0.3
B19: Company Credit Rating Available? | C19: Y
B20: Company is a Large Firm or Small Firm? | C20: L
B21: Provide Credit Rating | C21: Aaa/AAA
B22: Interest Coverage Ratio | C22: ='3Statement Model'!I28/-'3Statement Model'!I32 -> 34.167089
B23: ICR Based Corporate Default Spread | C23: =IF(C20="L",VLOOKUP('Input Sheet'!C22,'Damodaran Data'!H5:K20,4,TRUE),VLOOKUP(C22,'Damodaran Data'!H26:K41,4,TRUE)) -> 0.004
B24: Small Size Risk Premium
B25: Asset Specific Risk Premium

Sheet Damodaran Data
B3: Country | C3: Moody's rating | D3: Rating-based Default Spread | H3: For large non-financial service firms | N3: For financial service firms (default spreads are slighty different)
B4: India | C4: Baa3 | D4: 0.0187 | H4: If interest coverage ratio is | N4: If long term interest coverage ratio is
B5: Switzerland | C5: Aaa | D5: 0 | H5: > | I5: ≤ to | J5: Rating is | K5: Spread is | N5: greater than | O5: ≤ to | P5: Rating is | Q5: Spread is
B6: United Kingdom | C6: Aa3 | D6: 0.0051 | H6: -100000 | I6: 0.199999 | J6: D2/D | K6: 0.19 | N6: -100000 | O6: 0.049999 | P6: D2/D | Q6: 0.19
B7: United States | C7: Aa1 | D7: 0.0023 | H7: 0.2 | I7: 0.649999 | J7: C2/C | K7: 0.16 | N7: 0.05 | O7: 0.099999 | P7: C2/C | Q7: 0.16
B8: Abu Dhabi | C8: Aa2 | D8: 0.0042 | H8: 0.65 | I8: 0.799999 | J8: Ca2/CC | K8: 0.1261 | N8: 0.1 | O8: 0.199999 | P8: Ca2/CC | Q8: 0.1261
B9: Albania | C9: Ba3 | D9: 0.0306 | H9: 0.8 | I9: 1.249999 | J9: Caa/CCC | K9: 0.0885 | N9: 0.2 | O9: 0.299999 | P9: Caa/CCC | Q9: 0.0885
B10: Andorra (Principality of) | C10: Baa1 | D10: 0.0136 | H10: 1.25 | I10: 1.499999 | J10: B3/B- | K10: 0.0509 | N10: 0.3 | O10: 0.399999 | P10: B3/B- | Q10: 0.0509
B11: Angola | C11: B3 | D11: 0.0552 | H11: 1.5 | I11: 1.749999 | J11: B2/B | K11: 0.0321 | N11: 0.4 | O11: 0.499999 | P11: B2/B | Q11: 0.0321
B12: Argentina | C12: Caa1 | D12: 0.0637 | H12: 1.75 | I12: 1.999999 | J12: B1/B+ | K12: 0.0275 | N12: 0.5 | O12: 0.599999 | P12: B1/B+ | Q12: 0.0275
B13: Armenia | C13: Ba3 | D13: 0.0306 | H13: 2 | I13: 2.2499999 | J13: Ba2/BB | K13: 0.0184 | N13: 0.6 | O13: 0.749999 | P13: Ba2/BB | Q13: 0.0184
B14: Aruba | C14: Baa3 | D14: 0.0187 | H14: 2.25 | I14: 2.49999 | J14: Ba1/BB+ | K14: 0.0138 | N14: 0.75 | O14: 0.899999 | P14: Ba1/BB+ | Q14: 0.0138
B15: Australia | C15: Aaa | D15: 0 | H15: 2.5 | I15: 2.999999 | J15: Baa2/BBB | K15: 0.0111 | N15: 0.9 | O15: 1.199999 | P15: Baa2/BBB | Q15: 0.0111
B16: Austria | C16: Aa1 | D16: 0.0023 | H16: 3 | I16: 4.249999 | J16: A3/A- | K16: 0.0089 | N16: 1.2 | O16: 1.49999 | P16: A3/A- | Q16: 0.0089
B17: Azerbaijan | C17: Baa3 | D17: 0.0187 | H17: 4.25 | I17: 5.499999 | J17: A2/A | K17: 0.0078 | N17: 1.5 | O17: 1.99999 | P17: A2/A | Q17: 0.0078
... B20: Bangladesh | C20: B2 | D20: 0.0467 | H20: 8.5 | I20: 100000 | J20: Aaa/AAA | K20: 0.004 | N20: 3 | O20: 100000 | P20: Aaa/AAA | Q20: 0.004
B21: Barbados | C21: B2 | D21: 0.0467
B22: Belarus | C22: C | D22: 0.175
B23: Belgium | C23: Aa3 | D23: 0.0051
B24: Belize | C24: Caa1 | D24: 0.0637 | H24: For smaller and riskier firms
B25: Benin | C25: B1 | D25: 0.0383 | H25: If interest coverage ratio is
B26: Bermuda | C26: A2 | D26: 0.0072 | H26: greater than | I26: ≤ to | J26: Rating is | K26: Spread is
B27: Bolivia | C27: Ca | D27: 0.102 | H27: -100000 | I27: 0.499999 | J27: D2/D | K27: 0.19
B28: Bosnia and Herzegovina | C28: B3 | D28: 0.0552 | H28: 0.5 | I28: 0.799999 | J28: C2/C | K28: 0.16
B29: Botswana | C29: Baa1 | D29: 0.0136 | H29: 0.8 | I29: 1.249999 | J29: Ca2/CC | K29: 0.1261
B30: Brazil | C30: Ba1 | D30: 0.0213 | H30: 1.25 | I30: 1.499999 | J30: Caa/CCC | K30: 0.0885
B31: Bulgaria | C31: Baa1 | D31: 0.0136 | H31: 1.5 | I31: 1.999999 | J31: B3/B- | K31: 0.0509
B32: Burkina Faso | C32: Caa1 | D32: 0.0637 | H32: 2 | I32: 2.499999 | J32: B2/B | K32: 0.0321
B33: Cambodia | C33: B2 | D33: 0.0467 | H33: 2.5 | I33: 2.999999 | J33: B1/B+ | K33: 0.0275
B34: Cameroon | C34: Caa1 | D34: 0.0637 | H34: 3 | I34: 3.499999 | J34: Ba2/BB | K34: 0.0184
B35: Canada | C35: Aaa | D35: 0 | H35: 3.5 | I35: 3.9999999 | J35: Ba1/BB+ | K35: 0.0138
B36: Cape Verde | C36: B2 | D36: 0.0467 | H36: 4 | I36: 4.499999 | J36: Baa2/BBB | K36: 0.0111
B37: Cayman Islands | C37: Aa3 | D37: 0.0051 | H37: 4.5 | I37: 5.999999 | J37: A3/A- | K37: 0.0089
B38: Chile | C38: A2 | D38: 0.0072 | H38: 6 | I38: 7.499999 | J38: A2/A | K38: 0.0078
... B41: Congo (Democratic Republic of) | C41: B3 | D41: 0.0552 | H41: 12.5 | I41: 100000 | J41: Aaa/AAA | K41: 0.004
B42: Congo (Republic of) | C42: Caa2 | D42: 0.0765
B43: Cook Islands | C43: B1 | D43: 0.0383
B44: Costa Rica | C44: Ba2 | D44: 0.0256
B45: Côte d'Ivoire | C45: Ba2 | D45: 0.0256
B46: Croatia | C46: A3 | D46: 0.0102
...

Sheet Control Sheet
B2: ='Input Sheet'!C6 -> Hindustan Unilever Ltd.
B3: Control Sheet
G4: Current Case : | K4: 1
E8: Actual | K8: Explicit Forecast Period | P8: Maturity Period
B9: In Crs Unless Stated Otherwise | E9: 2020 | F9: =E9+1 -> 2021 | G9: =F9+1 -> 2022 | H9: =G9+1 -> 2023 | I9: =H9+1 -> 2024 | J9: =I9+1 -> 2025 | K9: =J9+1 -> 2026 | L9: =K9+1 -> 2027 | M9: =L9+1 -> 2028 | ... T9: =S9+1 -> 2035
A11: # | B11: Sales Assumptions
B13: Home Care
B15: Sales yoy % growth
B16: Management Case | E16: ='Assumptions Working'!G298 -> 0.059499767 | F16: ='Assumptions Working'!H298 -> 0.023240469 | G16: ='Assumptions Working'!I298 -> 0.18721788 | H16: ='Assumptions Working'!J298 -> 0.28141219 | I16: ='Assumptions Working'!K298 -> 0.027739839 | J16: 0.11 | K16: 0.11 | L16: 0.11 | M16: 0.11 | N16: 0.11 | O16: 0.11 | P16: 0.11 | Q16: 0.11 | R16: 0.1 | S16: 0.09 | T16: 0.08
B17: Street Case | E17: 0.059499767 | F17: 0.023240469 | G17: 0.18721788 | H17: 0.28141219 | I17: 0.027739839 | J17: 0.15 | K17: 0.15 | L17: 0.15 | M17: 0.15 | N17: 0.15 | O17: 0.15 | P17: 0.15 | Q17: 0.15 | R17: 0.15 | S17: 0.15 | T17: 0.15
B18: Worst Case | E18: 0.059499767 | F18: 0.023240469 | G18: 0.18721788 | H18: 0.28141219 | I18: 0.027739839 | J18: 0.06 | K18: 0.06 | L18: 0.06 | M18: 0.06 | N18: 0.06 | O18: 0.06 | P18: 0.06 | Q18: 0.06 | R18: 0.06 | S18: 0.06 | T18: 0.06
B19: ="Current Case- "&CHOOSE($K$4,$B$16,$B$17,$B$18) -> Current Case- Management Case | E19: =CHOOSE($K$4,E16,E17,E18) -> 0.059499767 | F19: =CHOOSE($K$4,F16,F17,F18) -> 0.023240469 | G19: =CHOOSE($K$4,G16,G17,G18) -> 0.18721788 | H19: =CHOOSE($K$4,H16,H17,H18) -> 0.28141219 | I19: =CHOOSE($K$4,I16,I17,I18) -> 0.027739839 | J19: =CHOOSE($K$4,J16,J17,J18) -> 0.11 | K19: =CHOOSE($K$4,K16,K17,K18) -> 0.11 | L19: =CHOOSE($K$4,L16,L17,L18) -> 0.11 | ... T19: =CHOOSE($K$4,T16,T17,T18) -> 0.08
B21: Personal Care
B23: Sales yoy % growth
B24: Management Case | E24: ='Assumptions Working'!G300 -> -0.01752809 | F24: ='Assumptions Working'!H300 -> 0.031450137 | G24: ='Assumptions Working'!I300 -> 0.084765495 | H24: ='Assumptions Working'!J300 -> 0.12546635 | I24: ='Assumptions Working'!K300 -> -0.40800109 | J24: ='Assumptions Working'!L300 -> 0.037278515 | K24: 0.06 | L24: 0.06 | M24: 0.06 | N24: 0.06 | O24: 0.06 | P24: 0.06 | Q24: 0.06 | R24: 0.06 | S24: 0.06 | T24: 0.06
B25: Street Case | E25: -0.01752809 | F25: 0.031450137 | G25: 0.084765495 | H25: 0.12546635 | I25: -0.40800109 | J25: 0.037278515 | K25: 0.1 | L25: 0.1 | M25: 0.1 | N25: 0.1 | O25: 0.1 | P25: 0.1 | Q25: 0.1 | R25: 0.1 | S25: 0.1 | T25: 0.1
B26: Worst Case | E26: -0.01752809 | F26: 0.031450137 | G26: 0.084765495 | H26: 0.12546635 | I26: -0.40800109 | J26: 0.037278515 | K26: 0.02 | L26: 0.02 | M26: 0.02 | N26: 0.02 | O26: 0.02 | P26: 0.02 | Q26: 0.02 | R26: 0.02 | S26: 0.02 | T26: 0.02
B27: ="Current Case- "&CHOOSE($K$4,$B$16,$B$17,$B$18) -> Current Case- Management Case | E27: =CHOOSE($K$4,E24,E25,E26) -> -0.01752809 | F27: =CHOOSE($K$4,F24,F25,F26) -> 0.031450137 | G27: =CHOOSE($K$4,G24,G25,G26) -> 0.084765495 | H27: =CHOOSE($K$4,H24,H25,H26) -> 0.12546635 | I27: =CHOOSE($K$4,I24,I25,I26) -> -0.40800109 | J27: =CHOOSE($K$4,J24,J25,J26) -> 0.037278515 | K27: =CHOOSE($K$4,K24,K25,K26) -> 0.06 | L27: =CHOOSE($K$4,L24,L25,L26) -> 0.06 | ... T27: =CHOOSE($K$4,T24,T25,T26) -> 0.06
B29: Baeuty & Wellbeing
B31: Sales yoy % growth
B32: Management Case | J32: ='Assumptions Working'!L302 -> -0.026033365 | K32: 0.13 | L32: 0.13 | M32: 0.13 | N32: 0.13 | O32: 0.13 | P32: 0.13 | Q32: 0.13 | R32: 0.13 | S32: 0.13 | T32: 0.13
B33: Street Case | J33: -0.026033365 | K33: 0.11 | L33: 0.11 | M33: 0.11 | N33: 0.11 | O33: 0.11 | P33: 0.11 | Q33: 0.11 | R33: 0.11 | S33: 0.11 | T33: 0.11
B34: Worst Case | J34: -0.026033365 | K34: 0.08 | L34: 0.08 | M34: 0.08 | N34: 0.08 | O34: 0.08 | P34: 0.08 | Q34: 0.08 | R34: 0.08 | S34: 0.08 | T34: 0.08
B35: ="Current Case- "&CHOOSE($K$4,$B$16,$B$17,$B$18) -> Current Case- Management Case | E35: =CHOOSE($K$4,E32,E33,E34) -> 0 | F35: =CHOOSE($K$4,F32,F33,F34) -> 0 | G35: =CHOOSE($K$4,G32,G33,G34) -> 0 | H35: =CHOOSE($K$4,H32,H33,H34) -> 0 | I35: =CHOOSE($K$4,I32,I33,I34) -> 0 | J35: =CHOOSE($K$4,J32,J33,J34) -> -0.026033365 | K35: =CHOOSE($K$4,K32,K33,K34) -> 0.13 | L35: =CHOOSE($K$4,L32,L33,L34) -> 0.13 | ... T35: =CHOOSE($K$4,T32,T33,T34) -> 0.13
B37: Foods
B39: Sales yoy % growth
B40: Management Case | E40: ='Assumptions Working'!F304 -> 0.10114268 | F40: ='Assumptions Working'!G304 -> 0.044734259 | G40: ='Assumptions Working'!H304 -> 0.77234899 | H40: ='Assumptions Working'!I304 -> 0.068236898 | I40: ='Assumptions Working'!J304 -> 0.054661468 | J40: ='Assumptions Working'!K304 -> 0.027897284 | K40: 0.06 | L40: 0.06 | M40: 0.06 | N40: 0.06 | O40: 0.06 | P40: 0.06 | Q40: 0.05 | R40: 0.04 | S40: 0.03 | T40: 0.02
B41: Street Case | E41: 0.10114268 | F41: 0.044734259 | G41: 0.77234899 | H41: 0.068236898 | I41: 0.054661468 | J41: 0.027897284 | K41: 0.08 | L41: 0.08 | M41: 0.08 | N41: 0.08 | O41: 0.08 | P41: 0.08 | Q41: 0.08 | R41: 0.08 | S41: 0.08 | T41: 0.08
B42: Worst Case | E42: 0.10114268 | F42: 0.044734259 | G42: 0.77234899 | H42: 0.068236898 | I42: 0.054661468 | J42: 0.027897284 | K42: 0.02 | L42: 0.02 | M42: 0.02 | N42: 0.02 | O42: 0.02 | P42: 0.02 | Q42: 0.02 | R42: 0.02 | S42: 0.02 | T42: 0.02
B43: ="Current Case- "&CHOOSE($K$4,$B$16,$B$17,$B$18) -> Current Case- Management Case | E43: =CHOOSE($K$4,E40,E41,E42) -> 0.10114268 | F43: =CHOOSE($K$4,F40,F41,F42) -> 0.044734259 | G43: =CHOOSE($K$4,G40,G41,G42) -> 0.77234899 | H43: =CHOOSE($K$4,H40,H41,H42) -> 0.068236898 | I43: =CHOOSE($K$4,I40,I41,I42) -> 0.054661468 | J43: =CHOOSE($K$4,J40,J41,J42) -> 0.027897284 | K43: =CHOOSE($K$4,K40,K41,K42) -> 0.06 | L43: =CHOOSE($K$4,L40,L41,L42) -> 0.06 | ... T43: =CHOOSE($K$4,T40,T41,T42) -> 0.02
B45: Others
B47: Sales yoy % growth
B48: Management Case | E48: ='Assumptions Working'!G306 -> -0.19933555 | F48: ='Assumptions Working'!H306 -> 0.51784232 | G48: ='Assumptions Working'!I306 -> 0.20503007 | H48: ='Assumptions Working'!J306 -> 0.11569873 | I48: ='Assumptions Working'!K306 -> -0.074827166 | J48: ='Assumptions Working'!L306 -> -0.041758242 | K48: 0.02 | L48: 0.02 | M48: 0.02 | N48: 0.02 | O48: 0.02 | P48: 0.02 | Q48: 0.02 | R48: 0.02 | S48: 0.02 | T48: 0.02
B49: Street Case | E49: -0.19933555 | F49: 0.51784232 | G49: 0.20503007 | H49: 0.11569873 | I49: -0.074827166 | J49: -0.041758242 | K49: 0.02 | L49: 0.02 | M49: 0.02 | N49: 0.02 | O49: 0.02 | P49: 0.02 | Q49: 0.02 | R49: 0.02 | S49: 0.02 | T49: 0.02
B50: Worst Case | E50: -0.19933555 | F50: 0.51784232 | G50: 0.20503007 | H50: 0.11569873 | I50: -0.074827166 | J50: -0.041758242 | K50: 0.01 | L50: 0.01 | M50: 0.01 | N50: 0.01 | O50: 0.01 | P50: 0.01 | Q50: 0.01 | R50: 0.01 | S50: 0.01 | T50: 0.01
B51: ="Current Case- "&CHOOSE($K$4,$B$16,$B$17,$B$18) -> Current Case- Management Case | E51: =CHOOSE($K$4,E48,E49,E50) -> -0.19933555 | F51: =CHOOSE($K$4,F48,F49,F50) -> 0.51784232 | G51: =CHOOSE($K$4,G48,G49,G50) -> 0.20503007 | H51: =CHOOSE($K$4,H48,H49,H50) -> 0.11569873 | I51: =CHOOSE($K$4,I48,I49,I50) -> -0.074827166 | J51: =CHOOSE($K$4,J48,J49,J50) -> -0.041758242 | K51: =CHOOSE($K$4,K48,K49,K50) -> 0.02 | L51: =CHOOSE($K$4,L48,L49,L50) -> 0.02 | ... T51: =CHOOSE($K$4,T48,T49,T50) -> 0.02
B53: Other Income
B55: yoy % growth
B56: Management Case | E56: ='Assumptions Working'!E349 -> 0.015886183 | F56: ='Assumptions Working'!F349 -> 0.0087182104 | G56: ='Assumptions Working'!G349 -> 0.0049193456 | H56: ='Assumptions Working'!H349 -> 0.0084516342 | I56: ='Assumptions Working'!I349 -> 0.013102624 | J56: ='Assumptions Working'!J349 -> 0.016111912 | K56: 0 | L56: 0 | M56: 0 | N56: 0 | O56: 0 | P56: 0 | Q56: 0 | R56: 0 | S56: 0 | T56: 0
B57: Street Case | E57: 0.015886183 | F57: 0.0087182104 | G57: 0.0049193456 | H57: 0.0084516342 | I57: 0.013102624 | J57: 0.016111912 | K57: 0 | L57: 0 | M57: 0 | N57: 0 | O57: 0 | P57: 0 | Q57: 0 | R57: 0 | S57: 0 | T57: 0
...

Sheet Schedules
B2: ='Input Sheet'!C6 -> Hindustan Unilever Ltd.
B3: Schedules
I4: Current Case:
E8: Actual | K8: Explicit Forecast Period | P8: Maturity Period
B9: In Crs Unless Stated Otherwise | E9: 2020 | F9: =E9+1 -> 2021 | G9: =F9+1 -> 2022 | H9: =G9+1 -> 2023 | I9: =H9+1 -> 2024 | J9: =I9+1 -> 2025 | K9: =J9+1 -> 2026 | L9: =K9+1 -> 2027 | M9: =L9+1 -> 2028 | ... T9: =S9+1 -> 2035
A11: # | B11: Sales Schedule
B13: Sales Breakup- Segment Wise
B15: Home Care | E15: 13640 | F15: 13957 | G15: 16570 | H15: 21233 | I15: 21822 | J15: 22958 | K15: =J15*(1+K22) -> 25483.38 | L15: =K15*(1+L22) -> 28286.552 | M15: =L15*(1+M22) -> 31398.072 | N15: =M15*(1+N22) -> 34851.86 | O15: =N15*(1+O22) -> 38685.565 | P15: =O15*(1+P22) -> 42940.977 | Q15: =P15*(1+Q22) -> 47664.485 | R15: =Q15*(1+R22) -> 52430.933 | ... T15: =S15*(1+T22) -> 61721.695
B16: Personal Care | E16: 17488 | F16: 18038 | G16: 19567 | H16: 22022 | I16: 13037 | J16: 13523 | K16: =J16*(1+K23) -> 14334.38 | L16: =K16*(1+L23) -> 15194.443 | M16: =L16*(1+M23) -> 16106.109 | N16: =M16*(1+N23) -> 17072.476 | O16: =N16*(1+O23) -> 18096.824 | P16: =O16*(1+P23) -> 19182.634 | Q16: =P16*(1+Q23) -> 20333.592 | R16: =Q16*(1+R23) -> 21553.608 | ... T16: =S16*(1+T23) -> 24217.633
B17: Beauty & Wellbeing | E17: 0 | F17: 0 | G17: 0 | H17: 0 | I17: 9411 | J17: 9166 | K17: =J17*(1+K24) -> 10357.58 | L17: =K17*(1+L24) -> 11704.065 | M17: =L17*(1+M24) -> 13225.594 | N17: =M17*(1+N24) -> 14944.921 | O17: =N17*(1+O24) -> 16887.761 | P17: =O17*(1+P24) -> 19083.17 | Q17: =P17*(1+Q24) -> 21563.982 | R17: =Q17*(1+R24) -> 24367.299 | ... T17: =S17*(1+T24) -> 31114.605
B18: Foods | E18: 7450 | F18: 13204 | G18: 14105 | H18: 14876 | I18: 15291 | J18: 15294 | K18: =J18*(1+K25) -> 16211.64 | L18: =K18*(1+L25) -> 17184.338 | M18: =L18*(1+M25) -> 18215.399 | N18: =M18*(1+N25) -> 19308.323 | O18: =N18*(1+O25) -> 20466.822 | P18: =O18*(1+P25) -> 21694.831 | Q18: =P18*(1+Q25) -> 22779.573 | R18: =Q18*(1+R25) -> 23690.756 | ... T18: =S18*(1+T25) -> 24889.508
B19: Others | E19: 1205 | F19: 1829 | G19: 2204 | H19: 2459 | I19: 2275 | J19: 2180 | K19: =J19*(1+K26) -> 2223.6 | L19: =K19*(1+L26) -> 2268.072 | M19: =L19*(1+M26) -> 2313.4334 | N19: =M19*(1+N26) -> 2359.7021 | O19: =N19*(1+O26) -> 2406.8962 | P19: =O19*(1+P26) -> 2455.0341 | Q19: =P19*(1+Q26) -> 2504.1348 | R19: =Q19*(1+R26) -> 2554.2175 | ... T19: =S19*(1+T26) -> 2657.4078
B20: Total Sales | E20: =SUM(E15:E19) -> 39783 | F20: =SUM(F15:F19) -> 47028 | G20: =SUM(G15:G19) -> 52446 | H20: =SUM(H15:H19) -> 60590 | I20: =SUM(I15:I19) -> 61836 | J20: =SUM(J15:J19) -> 63121 | K20: =SUM(K15:K19) -> 68610.58 | L20: =SUM(L15:L19) -> 74637.47 | ... T20: =SUM(T15:T19) -> 144600.85
B22: Home Care Sales % yoy | E22: ='Control Sheet'!E19 -> 0.059499767 | F22: ='Control Sheet'!F19 -> 0.023240469 | G22: ='Control Sheet'!G19 -> 0.18721788 | H22: ='Control Sheet'!H19 -> 0.28141219 | I22: ='Control Sheet'!I19 -> 0.027739839 | J22: ='Control Sheet'!J19 -> 0.11 | K22: ='Control Sheet'!K19 -> 0.11 | L22: ='Control Sheet'!L19 -> 0.11 | ... T22: ='Control Sheet'!T19 -> 0.08
B23: Personal Care Sales % yoy | E23: ='Control Sheet'!E27 -> -0.01752809 | F23: ='Control Sheet'!F27 -> 0.031450137 | G23: ='Control Sheet'!G27 -> 0.084765495 | H23: ='Control Sheet'!H27 -> 0.12546635 | I23: ='Control Sheet'!I27 -> -0.40800109 | J23: ='Control Sheet'!J27 -> 0.037278515 | K23: ='Control Sheet'!K27 -> 0.06 | L23: ='Control Sheet'!L27 -> 0.06 | ... T23: ='Control Sheet'!T27 -> 0.06
B24: Beauty & Wellbeing Sales % yoy | E24: ='Control Sheet'!E35 -> 0 | F24: ='Control Sheet'!F35 -> 0 | G24: ='Control Sheet'!G35 -> 0 | H24: ='Control Sheet'!H35 -> 0 | I24: ='Control Sheet'!I35 -> 0 | J24: ='Control Sheet'!J35 -> -0.026033365 | K24: ='Control Sheet'!K35 -> 0.13 | L24: ='Control Sheet'!L35 -> 0.13 | ... T24: ='Control Sheet'!T35 -> 0.13
B25: Foods Sales % yoy | E25: ='Control Sheet'!E43 -> 0.10114268 | F25: ='Control Sheet'!F43 -> 0.044734259 | G25: ='Control Sheet'!G43 -> 0.77234899 | H25: ='Control Sheet'!H43 -> 0.068236898 | I25: ='Control Sheet'!I43 -> 0.054661468 | J25: ='Control Sheet'!J43 -> 0.027897284 | K25: ='Control Sheet'!K43 -> 0.06 | L25: ='Control Sheet'!L43 -> 0.06 | ... T25: ='Control Sheet'!T43 -> 0.02
B26: Others Sales % yoy | E26: ='Control Sheet'!E51 -> -0.19933555 | F26: ='Control Sheet'!F51 -> 0.51784232 | G26: ='Control Sheet'!G51 -> 0.20503007 | H26: ='Control Sheet'!H51 -> 0.11569873 | I26: ='Control Sheet'!I51 -> -0.074827166 | J26: ='Control Sheet'!J51 -> -0.041758242 | K26: ='Control Sheet'!K51 -> 0.02 | L26: ='Control Sheet'!L51 -> 0.02 | ... T26: ='Control Sheet'!T51 -> 0.02
B27: Total Sales growth % yoy | K27: =K20/J20-1 -> 0.086969154 | L27: =L20/K20-1 -> 0.087841998 | M27: =M20/L20-1 -> 0.088710637 | N27: =N20/M20-1 -> 0.089574194 | O27: =O20/N20-1 -> 0.090431806 | P27: =P20/O20-1 -> 0.091282625 | Q27: =Q20/P20-1 -> 0.090066647 | R27: =R20/Q20-1 -> 0.084905587 | ... T27: =T20/S20-1 -> 0.074792631
B29: Other Income
B32: Other Income | E32: =' Income Statement'!D45 -> 632 | F32: =' Income Statement'!E45 -> 410 | G32: =' Income Statement'!F45 -> 258 | H32: =' Income Statement'!G45 -> 512 | I32: =' Income Statement'!H45 -> 811 | J32: =' Income Statement'!I45 -> 1017 | K32: =J32+(J32*K34) -> 1017 | L32: =K32+(K32*L34) -> 1017 | M32: =L32+(L32*M34) -> 1017 | N32: =M32+(M32*N34) -> 1017 | O32: =N32+(N32*O34) -> 1017 | P32: =O32+(O32*P34) -> 1017 | Q32: =P32+(P32*Q34) -> 1017 | R32: =Q32+(Q32*R34) -> 1017 | ... T32: =S32+(S32*T34) -> 1017
B34: Other Income % Revenue | E34: ='Assumptions Working'!E349 -> 0.015886183 | F34: ='Assumptions Working'!F349 -> 0.0087182104 | G34: ='Assumptions Working'!G349 -> 0.0049193456 | H34: ='Assumptions Working'!H349 -> 0.0084516342 | I34: ='Assumptions Working'!I349 -> 0.013102624 | J34: ='Assumptions Working'!J349 -> 0.016111912 | K34: ='Control Sheet'!K59 -> 0 | L34: ='Control Sheet'!L59 -> 0 | M34: ='Control Sheet'!M59 -> 0 | N34: ='Control Sheet'!N59 -> 0 | O34: ='Control Sheet'!O59 -> 0 | P34: ='Control Sheet'!P59 -> 0 | Q34: ='Control Sheet'!Q59 -> 0 | R34: ='Control Sheet'!R59 -> 0 | ... T34: ='Control Sheet'!T59 -> 0
A38: # | B38: COGS Schedule
B40: COGS | E40: =-' Income Statement'!D20 -> 18259 | F40: =-' Income Statement'!E20 -> 22148 | G40: =-' Income Statement'!F20 -> 25735 | H40: =-' Income Statement'!G20 -> 31716 | I40: =-' Income Statement'!H20 -> 29760 | J40: =-' Income Statement'!I20 -> 30578 | K40: =K20*K42 -> 33619.184 | L40: =L20*L42 -> 36404.426 | M40: =M20*M42 -> 39451.054 | N40: =N20*N42 -> 42785.642 | O40: =O20*O42 -> 46437.601 | P40: =P20*P42 -> 50676.547 | Q40: =Q20*Q42 -> 55240.814 | R40: =R20*R42 -> 59931.067 | ... T40: =T20*T42 -> 69553.008
B42: COGS % Sales | E42: ='Control Sheet'!E71 -> 0.45896488 | F42: ='Control Sheet'!F71 -> 0.47095347 | G42: ='Control Sheet'!G71 -> 0.49069519 | H42: ='Control Sheet'!H71 -> 0.52353912 | I42: ='Control Sheet'!I71 -> 0.48080651 | J42: ='Control Sheet'!J71 -> 0.48443466 | K42: ='Control Sheet'!K71 -> 0.49 | L42: ='Control Sheet'!L71 -> 0.48775 | ... T42: ='Control Sheet'!T71 -> 0.481
B43: Gross Margin % Sales | E43: =100%-E42 -> 0.54103512 | F43: =100%-F42 -> 0.52904653 | G43: =100%-G42 -> 0.50930481 | H43: =100%-H42 -> 0.47646088 | I43: =100%-I42 -> 0.51919349 | J43: =100%-J42 -> 0.51556534 | K43: =100%-K42 -> 0.51 | L43: =100%-L42 -> 0.51225 | ... T43: =100%-T42 -> 0.519
A45: # | B45: SG&A Schedule
B47: Employee Benefit Expenses
B50: Employee Benefit Expenses | E50: =-' Income Statement'!D33 -> 1820 | F50: =-' Income Statement'!E33 -> 2358 | G50: =-' Income Statement'!F33 -> 2545 | H50: =-' Income Statement'!G33 -> 2854 | I50: =-' Income Statement'!H33 -> 3009 | J50: =-' Income Statement'!I33 -> 3077 | K50: =K20*K53 -> 3293.3078 | L50: =L20*L53 -> 3582.5986 | M50: =M20*M53 -> 3900.4132 | N50: =N20*N53 -> 4249.7895 | O50: =O20*O53 -> 4634.1057 | P50: =P20*P53 -> 5057.119 | Q50: =Q20*Q53 -> 5512.5968 | R50: =R20*R53 -> 5980.647 | ... T50: =T20*T53 -> 6940.8407
B51: Total Employee Benefit Expenses | E51: =E50 -> 1820 | F51: =F50 -> 2358 | G51: =G50 -> 2545 | H51: =H50 -> 2854 | I51: =I50 -> 3009 | J51: =J50 -> 3077 | K51: =K50 -> 3293.3078 | L51: =L50 -> 3582.5986 | ... T51: =T50 -> 6940.8407
B53: Employee Benefit Expenses % Sales | E53: ='Control Sheet'!E80 -> 0.045748184 | F53: ='Control Sheet'!F80 -> 0.050140342 | G53: ='Control Sheet'!G80 -> 0.048526103 | H53: ='Control Sheet'!H80 -> 0.047111258 | I53: ='Control Sheet'!I80 -> 0.048613804 | J53: ='Control Sheet'!J80 -> 0.047638662 | K53: ='Control Sheet'!K80 -> 0.048 | L53: ='Control Sheet'!L80 -> 0.048 | ... T53: ='Control Sheet'!T80 -> 0.048
B54: Other Expenses % yoy growth | F54: =F51/E51-1 -> 0.2956044 | G54: =G51/F51-1 -> 0.079304495 | H54: =H51/G51-1 -> 0.12141454 | I54: =I51/H51-1 -> 0.054309741 | J54: =J51/I51-1 -> 0.02259887 | K54: =K51/J51-1 -> 0.070298291 | L54: =L51/K51-1 -> 0.087841998 | M54: =M51/L51-1 -> 0.088710637 | ... T54: =T51/S51-1 -> 0.074792631
B56: Other Expenses
B59: Other Expenses | E59: =-' Income Statement'!D34 -> 9843 | F59: =-' Income Statement'!E34 -> 10896 | G59: =-' Income Statement'!F34 -> 11309 | H59: =-' Income Statement'!G34 -> 11861 | I59: =-' Income Statement'!H34 -> 14464 | J59: =-' Income Statement'!I34 -> 14615 | K59: =K20*K62 -> 15917.655 | L59: =L20*L62 -> 17315.893 | M59: =M20*M62 -> 18851.997 | N59: =N20*N62 -> 20540.649 | O59: =O20*O62 -> 22398.178 | P59: =P20*P62 -> 24442.742 | Q59: =Q20*Q62 -> 26644.218 | R59: =R20*R62 -> 28906.461 | ... T59: =T20*T62 -> 33547.397
B60: Total Other Expenses | E60: =E59 -> 9843 | F60: =F59 -> 10896 | G60: =G59 -> 11309 | H60: =H59 -> 11861 | I60: =I59 -> 14464 | J60: =J59 -> 14615 | K60: =K59 -> 15917.655 | L60: =L59 -> 17315.893 | ... T60: =T59 -> 33547.397
B62: Other Expenses % Sales | E62: ='Control Sheet'!E86 -> 0.24741724 | F62: ='Control Sheet'!F86 -> 0.23169176 | G62: ='Control Sheet'!G86 -> 0.21563132 | H62: ='Control Sheet'!H86 -> 0.19579069 | I62: ='Control Sheet'!I86 -> 0.23368231 | J62: ='Control Sheet'!J86 -> 0.23153942 | K62: ='Control Sheet'!K86 -> 0.232 | L62: ='Control Sheet'!L86 -> 0.232 | ... T62: ='Control Sheet'!T86 -> 0.232
B63: Other Expenses % yoy growth | F63: =F60/E60-1 -> 0.10697958 | G63: =G60/F60-1 -> 0.037903818 | H63: =H60/G60-1 -> 0.048810682 | I63: =I60/H60-1 -> 0.21945873 | J63: =J60/I60-1 -> 0.010439712 | K63: =K60/J60-1 -> 0.089131342 | L63: =L60/K60-1 -> 0.087841998 | M63: =M60/L60-1 -> 0.088710637 | ... T63: =T60/S60-1 -> 0.074792631
B65: Total SG&A Expense (Excluding Depriciation & Interest Expense) | E65: =E51+E60 -> 11663 | F65: =F51+F60 -> 13254 | G65: =G51+G60 -> 13854 | H65: =H51+H60 -> 14715 | I65: =I51+I60 -> 17473 | J65: =J51+J60 -> 17692 | K65: =K51+K60 -> 19210.962 | L65: =L51+L60 -> 20898.492 | ... T65: =T51+T60 -> 40488.238
B66: Total SG&A % Sales | E66: =E65/E20 -> 0.29316542 | F66: =F65/F20 -> 0.2818321 | G66: =G65/G20 -> 0.26415742 | H66: =H65/H20 -> 0.24286186 | I66: =I65/I20 -> 0.28257002 | J66: =J65/J20 -> 0.28028707 | K66: =K65/K20 -> 0.28 | L66: =L65/L20 -> 0.28 | ... T66: =T65/T20 -> 0.28
A68: # | B68: Non-Current Asset Schedule
...

Sheet 3Statement Model
B2: ='Input Sheet'!C6 -> Hindustan Unilever Ltd.
B3: 3 Statement Model
I4: Current Case:
U7: CAGR
D8: Actual | J8: Explicit Forecast Period | O8: Maturity Period | U8: 5 Years | V8: 3 Years
B9: In Crs Unless Stated Otherwise | D9: 2020 | E9: =D9+1 -> 2021 | F9: =E9+1 -> 2022 | G9: =F9+1 -> 2023 | H9: =G9+1 -> 2024 | I9: =H9+1 -> 2025 | J9: =I9+1 -> 2026 | K9: =J9+1 -> 2027 | L9: =K9+1 -> 2028 | ... S9: =R9+1 -> 2035
A11: # | B11: Income Statement
B13: Revenue From Operations | D13: =INDEX(' Income Statement'!$D$7:$I$62,MATCH('3Statement Model'!$B13,' Income Statement'!$B$7:$B$62,0),MATCH('3Statement Model'!D$9,' Income Statement'!$D$6:$I$6,)) -> 39783 | E13: =Schedules!F20 -> 47028 | F13: =Schedules!G20 -> 52446 | G13: =Schedules!H20 -> 60590 | H13: =Schedules!I20 -> 61836 | I13: =Schedules!J20 -> 63121 | J13: =Schedules!K20 -> 68610.58 | K13: =Schedules!L20 -> 74637.47 | L13: =Schedules!M20 -> 81258.608 | ... S13: =Schedules!T20 -> 144600.85 | U13: =_xlfn.RRI(5,I13,N13) -> 0.088704869 | V13: =_xlfn.RRI(3,I13,L13) -> 0.087840364
B14: Less: Cost of Goods Sold | D14: =' Income Statement'!D20 -> -18259 | E14: =' Income Statement'!E20 -> -22148 | F14: =' Income Statement'!F20 -> -25735 | G14: =' Income Statement'!G20 -> -31716 | H14: =' Income Statement'!H20 -> -29760 | I14: =' Income Statement'!I20 -> -30578 | J14: =-Schedules!K40 -> -33619.184 | K14: =-Schedules!L40 -> -36404.426 | L14: =-Schedules!M40 -> -39451.054 | M14: =-Schedules!N40 -> -42785.642 | N14: =-Schedules!O40 -> -46437.601 | O14: =-Schedules!P40 -> -50676.547 | P14: =-Schedules!Q40 -> -55240.814 | Q14: =-Schedules!R40 -> -59931.067 | ... S14: =-Schedules!T40 -> -69553.008 | U14: =_xlfn.RRI(5,I14,N14) -> 0.087156682 | V14: =_xlfn.RRI(3,I14,L14) -> 0.08863722
B15: Gross Profit | D15: =SUM(D13:D14) -> 21524 | E15: =SUM(E13:E14) -> 24880 | F15: =SUM(F13:F14) -> 26711 | G15: =SUM(G13:G14) -> 28874 | H15: =SUM(H13:H14) -> 32076 | I15: =SUM(I13:I14) -> 32543 | J15: =SUM(J13:J14) -> 34991.396 | K15: =SUM(K13:K14) -> 38233.044 | ... S15: =SUM(S13:S14) -> 75047.84
B17: Less: SG&A (Excluding Depriciation & Interest)
B18: Employee Benefit Expenses | D18: =' Income Statement'!D33 -> -1820 | E18: =' Income Statement'!E33 -> -2358 | F18: =' Income Statement'!F33 -> -2545 | G18: =' Income Statement'!G33 -> -2854 | H18: =' Income Statement'!H33 -> -3009 | I18: =' Income Statement'!I33 -> -3077 | J18: =-Schedules!K51 -> -3293.3078 | K18: =-Schedules!L51 -> -3582.5986 | L18: =-Schedules!M51 -> -3900.4132 | M18: =-Schedules!N51 -> -4249.7895 | N18: =-Schedules!O51 -> -4634.1057 | O18: =-Schedules!P51 -> -5057.119 | P18: =-Schedules!Q51 -> -5512.5968 | Q18: =-Schedules!R51 -> -5980.647 | ... S18: =-Schedules!T51 -> -6940.8407 | U18: =_xlfn.RRI(5,I18,N18) -> 0.085344695 | V18: =_xlfn.RRI(3,I18,L18) -> 0.082250279
B19: Othere Expenses | D19: =' Income Statement'!D34 -> -9843 | E19: =' Income Statement'!E34 -> -10896 | F19: =' Income Statement'!F34 -> -11309 | G19: =' Income Statement'!G34 -> -11861 | H19: =' Income Statement'!H34 -> -14464 | I19: =' Income Statement'!I34 -> -14615 | J19: =-Schedules!K60 -> -15917.655 | K19: =-Schedules!L60 -> -17315.893 | L19: =-Schedules!M60 -> -18851.997 | M19: =-Schedules!N60 -> -20540.649 | N19: =-Schedules!O60 -> -22398.178 | O19: =-Schedules!P60 -> -24442.742 | P19: =-Schedules!Q60 -> -26644.218 | Q19: =-Schedules!R60 -> -28906.461 | ... S19: =-Schedules!T60 -> -33547.397 | U19: =_xlfn.RRI(5,I19,N19) -> 0.089137653 | V19: =_xlfn.RRI(3,I19,L19) -> 0.088561193
B20: Total SG&A | D20: =SUM(D18:D19) -> -11663 | E20: =SUM(E18:E19) -> -13254 | F20: =SUM(F18:F19) -> -13854 | G20: =SUM(G18:G19) -> -14715 | H20: =SUM(H18:H19) -> -17473 | I20: =SUM(I18:I19) -> -17692 | J20: =SUM(J18:J19) -> -19210.962 | K20: =SUM(K18:K19) -> -20898.492 | ... S20: =SUM(S18:S19) -> -40488.238
B22: EBITDA | D22: =D15+D20 -> 9861 | E22: =E15+E20 -> 11626 | F22: =F15+F20 -> 12857 | G22: =G15+G20 -> 14159 | H22: =H15+H20 -> 14603 | I22: =I15+I20 -> 14851 | J22: =J15+J20 -> 15780.433 | K22: =K15+K20 -> 17334.553 | ... S22: =S15+S20 -> 34559.603
B24: EBITDA Margins% | D24: =D22/D13 -> 0.24786969 | E24: =E22/E13 -> 0.24721443 | F24: =F22/F13 -> 0.24514739 | G24: =G22/G13 -> 0.23368543 | H24: =H22/H13 -> 0.23615693 | I24: =I22/I13 -> 0.23527828 | J24: =J22/J13 -> 0.23 | K24: =K22/K13 -> 0.23225 | ... S24: =S22/S13 -> 0.239
B27: Less: Depreciation & Amortization | D27: =' Income Statement'!D41 -> -1002 | E27: =Schedules!F146 -> -1074 | F27: =Schedules!G146 -> -1091 | G27: =Schedules!H146 -> -1137 | H27: =Schedules!I146 -> -1216 | I27: =Schedules!J146 -> -1355 | J27: =Schedules!K146 -> -1530.8597 | K27: =Schedules!L146 -> -1704.3912 | L27: =Schedules!M146 -> -1893.436 | ... S27: =Schedules!T146 -> -3776.3996 | U27: =_xlfn.RRI(5,I27,N27) -> 0.11397483 | V27: =_xlfn.RRI(3,I27,L27) -> 0.11798792
B28: Earnings Before Interest & Tax | D28: =SUM(D22,D27:D27) -> 8859 | E28: =SUM(E22,E27:E27) -> 10552 | F28: =SUM(F22,F27:F27) -> 11766 | G28: =SUM(G22,G27:G27) -> 13022 | H28: =SUM(H22,H27:H27) -> 13387 | I28: =SUM(I22,I27:I27) -> 13496 | J28: =SUM(J22,J27:J27) -> 14249.574 | K28: =SUM(K22,K27:K27) -> 15630.161 | ... S28: =SUM(S22,S27:S27) -> 30783.203
B30: EBIT Margins% | D30: =D28/D13 -> 0.22268306 | E30: =E28/E13 -> 0.22437697 | F30: =F28/F13 -> 0.22434504 | G30: =G28/G13 -> 0.21491995 | H30: =H28/H13 -> 0.21649201 | I30: =I28/I13 -> 0.21381157 | J30: =J28/J13 -> 0.2076877 | K30: =K28/K13 -> 0.2094144 | ... S30: =S28/S13 -> 0.21288397
B32: Less: Finance Costs | D32: =INDEX(' Income Statement'!$D$7:$I$62,MATCH('3Statement Model'!$B32,' Income Statement'!$B$7:$B$62,0),MATCH('3Statement Model'!D$9,' Income Statement'!$D$6:$I$6,)) -> -118 | E32: =INDEX(' Income Statement'!$D$7:$I$62,MATCH('3Statement Model'!$B32,' Income Statement'!$B$7:$B$62,0),MATCH('3Statement Model'!E$9,' Income Statement'!$D$6:$I$6,)) -> -117 | F32: =INDEX(' Income Statement'!$D$7:$I$62,MATCH('3Statement Model'!$B32,' Income Statement'!$B$7:$B$62,0),MATCH('3Statement Model'!F$9,' Income Statement'!$D$6:$I$6,)) -> -106 | G32: =INDEX(' Income Statement'!$D$7:$I$62,MATCH('3Statement Model'!$B32,' Income Statement'!$B$7:$B$62,0),MATCH('3Statement Model'!G$9,' Income Statement'!$D$6:$I$6,)) -> -114 | H32: =INDEX(' Income Statement'!$D$7:$I$62,MATCH('3Statement Model'!$B32,' Income Statement'!$B$7:$B$62,0),MATCH('3Statement Model'!H$9,' Income Statement'!$D$6:$I$6,)) -> -334 | I32: =INDEX(' Income Statement'!$D$7:$I$62,MATCH('3Statement Model'!$B32,' Income Statement'!$B$7:$B$62,0),MATCH('3Statement Model'!I$9,' Income Statement'!$D$6:$I$6,)) -> -395 | J32: =-Schedules!K202 -> -266.84209 | K32: =-Schedules!L202 -> -290.28203 | L32: =-Schedules!M202 -> -316.03314 | M32: =-Schedules!N202 -> -344.34155 | N32: =-Schedules!O202 -> -375.48098 | O32: =-Schedules!P202 -> -409.75587 | P32: =-Schedules!Q202 -> -446.66121 | Q32: =-Schedules!R202 -> -484.58524 | ... S32: =-Schedules!T202 -> -562.38546 | U32: =_xlfn.RRI(5,I32,N32) -> -0.010084397 | V32: =_xlfn.RRI(3,I32,L32) -> -0.071649785
B33: Add: Other Income | D33: =INDEX(' Income Statement'!$D$7:$I$62,MATCH('3Statement Model'!$B33,' Income Statement'!$B$7:$B$62,0),MATCH('3Statement Model'!D$9,' Income Statement'!$D$6:$I$6,)) -> 632 | E33: =INDEX(' Income Statement'!$D$7:$I$62,MATCH('3Statement Model'!$B33,' Income Statement'!$B$7:$B$62,0),MATCH('3Statement Model'!E$9,' Income Statement'!$D$6:$I$6,)) -> 410 | F33: =INDEX(' Income Statement'!$D$7:$I$62,MATCH('3Statement Model'!$B33,' Income Statement'!$B$7:$B$62,0),MATCH('3Statement Model'!F$9,' Income Statement'!$D$6:$I$6,)) -> 258 | G33: =INDEX(' Income Statement'!$D$7:$I$62,MATCH('3Statement Model'!$B33,' Income Statement'!$B$7:$B$62,0),MATCH('3Statement Model'!G$9,' Income Statement'!$D$6:$I$6,)) -> 512 | H33: =INDEX(' Income Statement'!$D$7:$I$62,MATCH('3Statement Model'!$B33,' Income Statement'!$B$7:$B$62,0),MATCH('3Statement Model'!H$9,' Income Statement'!$D$6:$I$6,)) -> 811 | I33: =INDEX(' Income Statement'!$D$7:$I$62,MATCH('3Statement Model'!$B33,' Income Statement'!$B$7:$B$62,0),MATCH('3Statement Model'!I$9,' Income Statement'!$D$6:$I$6,)) -> 1017 | J33: =Schedules!K32 -> 1017 | K33: =Schedules!L32 -> 1017 | L33: =Schedules!M32 -> 1017 | M33: =Schedules!N32 -> 1017 | N33: =Schedules!O32 -> 1017 | O33: =Schedules!P32 -> 1017 | P33: =Schedules!Q32 -> 1017 | Q33: =Schedules!R32 -> 1017 | ... S33: =Schedules!T32 -> 1017 | U33: =_xlfn.RRI(5,I33,N33) -> 0 | V33: =_xlfn.RRI(3,I33,L33) -> 0
B34: Add/(Less): Share Of Profit/Loss Of Associates | D34: =INDEX(' Income Statement'!$D$7:$I$62,MATCH('3Statement Model'!$B34,' Income Statement'!$B$7:$B$62,0),MATCH('3Statement Model'!D$9,' Income Statement'!$D$6:$I$6,)) -> 0 | E34: =INDEX(' Income Statement'!$D$7:$I$62,MATCH('3Statement Model'!$B34,' Income Statement'!$B$7:$B$62,0),MATCH('3Statement Model'!E$9,' Income Statement'!$D$6:$I$6,)) -> 0 | F34: =INDEX(' Income Statement'!$D$7:$I$62,MATCH('3Statement Model'!$B34,' Income Statement'!$B$7:$B$62,0),MATCH('3Statement Model'!F$9,' Income Statement'!$D$6:$I$6,)) -> 0 | G34: =INDEX(' Income Statement'!$D$7:$I$62,MATCH('3Statement Model'!$B34,' Income Statement'!$B$7:$B$62,0),MATCH('3Statement Model'!G$9,' Income Statement'!$D$6:$I$6,)) -> -1 | H34: =INDEX(' Income Statement'!$D$7:$I$62,MATCH('3Statement Model'!$B34,' Income Statement'!$B$7:$B$62,0),MATCH('3Statement Model'!H$9,' Income Statement'!$D$6:$I$6,)) -> -4 | I34: =INDEX(' Income Statement'!$D$7:$I$62,MATCH('3Statement Model'!$B34,' Income Statement'!$B$7:$B$62,0),MATCH('3Statement Model'!I$9,' Income Statement'!$D$6:$I$6,)) -> -8 | J34: 0 | K34: 0 | L34: 0 | M34: 0 | N34: 0 | O34: 0 | P34: 0 | Q34: 0 | R34: 0 | S34: 0
B35: Add/(Less): Exceptional Items | D35: =INDEX(' Income Statement'!$D$7:$I$62,MATCH('3Statement Model'!$B35,' Income Statement'!$B$7:$B$62,0),MATCH('3Statement Model'!D$9,' Income Statement'!$D$6:$I$6,)) -> -200 | E35: =INDEX(' Income Statement'!$D$7:$I$62,MATCH('3Statement Model'!$B35,' Income Statement'!$B$7:$B$62,0),MATCH('3Statement Model'!E$9,' Income Statement'!$D$6:$I$6,)) -> -239 | F35: =INDEX(' Income Statement'!$D$7:$I$62,MATCH('3Statement Model'!$B35,' Income Statement'!$B$7:$B$62,0),MATCH('3Statement Model'!F$9,' Income Statement'!$D$6:$I$6,)) -> -44 | G35: =INDEX(' Income Statement'!$D$7:$I$62,MATCH('3Statement Model'!$B35,' Income Statement'!$B$7:$B$62,0),MATCH('3Statement Model'!G$9,' Income Statement'!$D$6:$I$6,)) -> -64 | H35: =INDEX(' Income Statement'!$D$7:$I$62,MATCH('3Statement Model'!$B35,' Income Statement'!$B$7:$B$62,0),MATCH('3Statement Model'!H$9,' Income Statement'!$D$6:$I$6,)) -> 6 | I35: =INDEX(' Income Statement'!$D$7:$I$62,MATCH('3Statement Model'!$B35,' Income Statement'!$B$7:$B$62,0),MATCH('3Statement Model'!I$9,' Income Statement'!$D$6:$I$6,)) -> 305 | J35: 0 | K35: 0 | L35: 0 | M35: 0 | N35: 0 | O35: 0 | P35: 0 | Q35: 0 | R35: 0 | S35: 0
B37: Earnings Before Tax | D37: =SUM(D28,D32:D35) -> 9173 | E37: =SUM(E28,E32:E35) -> 10606 | F37: =SUM(F28,F32:F35) -> 11874 | G37: =SUM(G28,G32:G35) -> 13355 | H37: =SUM(H28,H32:H35) -> 13866 | I37: =SUM(I28,I32:I35) -> 14415 | J37: =SUM(J28,J32:J33) -> 14999.732 | K37: =SUM(K28,K32:K33) -> 16356.879 | L37: =SUM(L28,L32:L33) -> 17862.674 | M37: =SUM(M28,M32:M33) -> 19534.317 | N37: =SUM(N28,N32:N33) -> 21391.075 | O37: =SUM(O28,O32:O33) -> 23217.219 | P37: =SUM(P28,P32:P33) -> 25180.153 | Q37: =SUM(Q28,Q32:Q33) -> 27182.598 | ... S37: =SUM(S28,S32:S33) -> 31237.818
B39: Less: Tax Expenses | D39: =INDEX(' Income Statement'!$D$7:$I$62,MATCH('3Statement Model'!$B39,' Income Statement'!$B$7:$B$62,0),MATCH('3Statement Model'!D$9,' Income Statement'!$D$6:$I$6,)) -> -2409 | E39: =INDEX(' Income Statement'!$D$7:$I$62,MATCH('3Statement Model'!$B39,' Income Statement'!$B$7:$B$62,0),MATCH('3Statement Model'!E$9,' Income Statement'!$D$6:$I$6,)) -> -2606 | F39: =INDEX(' Income Statement'!$D$7:$I$62,MATCH('3Statement Model'!$B39,' Income Statement'!$B$7:$B$62,0),MATCH('3Statement Model'!F$9,' Income Statement'!$D$6:$I$6,)) -> -2987 | G39: =INDEX(' Income Statement'!$D$7:$I$62,MATCH('3Statement Model'!$B39,' Income Statement'!$B$7:$B$62,0),MATCH('3Statement Model'!G$9,' Income Statement'!$D$6:$I$6,)) -> -3201 | H39: =INDEX(' Income Statement'!$D$7:$I$62,MATCH('3Statement Model'!$B39,' Income Statement'!$B$7:$B$62,0),MATCH('3Statement Model'!H$9,' Income Statement'!$D$6:$I$6,)) -> -3644 | I39: =INDEX(' Income Statement'!$D$7:$I$62,MATCH('3Statement Model'!$B39,' Income Statement'!$B$7:$B$62,0),MATCH('3Statement Model'!I$9,' Income Statement'!$D$6:$I$6,)) -> -3744 | J39: =Schedules!K170 -> -4499.9195 | K39: =Schedules!L170 -> -4907.0638 | L39: =Schedules!M170 -> -5358.8023 | M39: =Schedules!N170 -> -5860.295 | N39: =Schedules!O170 -> -6417.3226 | O39: =Schedules!P170 -> -6965.1656 | P39: =Schedules!Q170 -> -7554.0458 | Q39: =Schedules!R170 -> -8154.7794 | ... S39: =Schedules!T170 -> -9371.3453 | U39: =_xlfn.RRI(5,I39,N39) -> 0.11379075 | V39: =_xlfn.RRI(3,I39,L39) -> 0.12696553
B40: Net Income | D40: =SUM(D37:D39) -> 6764 | E40: =SUM(E37:E39) -> 8000 | F40: =SUM(F37:F39) -> 8887 | G40: =SUM(G37:G39) -> 10154 | H40: =SUM(H37:H39) -> 10222 | I40: =SUM(I37:I39) -> 10671 | J40: =SUM(J37:J39) -> 10499.812 | K40: =SUM(K37:K39) -> 11449.815 | ... S40: =SUM(S37:S39) -> 21866.472
B42: Sales Growth % | G42: =IFERROR(G13/F13-1,"NM") -> 0.15528353 | H42: =IFERROR(H13/G13-1,"NM") -> 0.02056445 | I42: =IFERROR(I13/H13-1,"NM") -> 0.020780775 | J42: =IFERROR(J13/I13-1,"NM") -> 0.086969154 | K42: =IFERROR(K13/J13-1,"NM") -> 0.087841998 | L42: =IFERROR(L13/K13-1,"NM") -> 0.088710637 | M42: =IFERROR(M13/L13-1,"NM") -> 0.089574194 | N42: =IFERROR(N13/M13-1,"NM") -> 0.090431806 | ... S42: =IFERROR(S13/R13-1,"NM") -> 0.074792631
B43: Gross Profit Margins % | G43: =G15/G13 -> 0.47654729 | H43: =H15/H13 -> 0.51872696 | I43: =I15/I13 -> 0.51556534 | J43: =J15/J13 -> 0.51 | K43: =K15/K13 -> 0.51225 | L43: =L15/L13 -> 0.5145 | M43: =M15/M13 -> 0.51675 | N43: =N15/N13 -> 0.519 | ... S43: =S15/S13 -> 0.519
B44: EBITDA Margins % | G44: =G22/G13 -> 0.23368543 | H44: =H22/H13 -> 0.23615693 | I44: =I22/I13 -> 0.23527828 | J44: =J22/J13 -> 0.23 | K44: =K22/K13 -> 0.23225 | L44: =L22/L13 -> 0.2345 | M44: =M22/M13 -> 0.23675 | N44: =N22/N13 -> 0.239 | ... S44: =S22/S13 -> 0.239
B45: EBIT Margins % | G45: =G28/G13 -> 0.21491995 | H45: =H28/H13 -> 0.21649201 | I45: =I28/I13 -> 0.21381157 | J45: =J28/J13 -> 0.2076877 | K45: =K28/K13 -> 0.2094144 | L45: =L28/L13 -> 0.21119864 | M45: =M28/M13 -> 0.21303634 | N45: =N28/N13 -> 0.2149236 | ... S45: =S28/S13 -> 0.21288397
B46: Actual Tax Rate % | G46: =-G39/G37 -> 0.23968551 | H46: =-H39/H37 -> 0.2628011 | I46: =-I39/I37 -> 0.25972945 | J46: =-J39/J37 -> 0.3 | K46: =-K39/K37 -> 0.3 | L46: =-L39/L37 -> 0.3 | M46: =-M39/M37 -> 0.3 | N46: =-N39/N37 -> 0.3 | ... S46: =-S39/S37 -> 0.3
B47: Net Income Margin % | G47: =G40/G13 -> 0.16758541 | H47: =H40/H13 -> 0.16530823 | I47: =I40/I13 -> 0.16905626 | J47: =J40/J13 -> 0.15303488 | K47: =K40/K13 -> 0.15340573 | L47: =L40/L13 -> 0.15387751 | M47: =M40/M13 -> 0.15444366 | N47: =N40/N13 -> 0.15509791 | ... S47: =S40/S13 -> 0.15121953
A49: # | B49: Balance Sheet
B51: EQUITIES AND LIABILITIES
B52: SHAREHOLDER'S FUNDS
B53: Equity Share Capital | D53: =INDEX('Balance Sheet'!$D$9:$I$65,MATCH('3Statement Model'!$B53,'Balance Sheet'!$B$9:$B$65,0),MATCH('3Statement Model'!D$9,'Balance Sheet'!$D$6:$I$6,0)) -> 216 | E53: =INDEX('Balance Sheet'!$D$9:$I$65,MATCH('3Statement Model'!$B53,'Balance Sheet'!$B$9:$B$65,0),MATCH('3Statement Model'!E$9,'Balance Sheet'!$D$6:$I$6,0)) -> 235 | F53: =INDEX('Balance Sheet'!$D$9:$I$65,MATCH('3Statement Model'!$B53,'Balance Sheet'!$B$9:$B$65,0),MATCH('3Statement Model'!F$9,'Balance Sheet'!$D$6:$I$6,0)) -> 235 | G53: =INDEX('Balance Sheet'!$D$9:$I$65,MATCH('3Statement Model'!$B53,'Balance Sheet'!$B$9:$B$65,0),MATCH('3Statement Model'!G$9,'Balance Sheet'!$D$6:$I$6,0)) -> 235 | H53: =INDEX('Balance Sheet'!$D$9:$I$65,MATCH('3Statement Model'!$B53,'Balance Sheet'!$B$9:$B$65,0),MATCH('3Statement Model'!H$9,'Balance Sheet'!$D$6:$I$6,0)) -> 235 | I53: =INDEX('Balance Sheet'!$D$9:$I$65,MATCH('3Statement Model'!$B53,'Balance Sheet'!$B$9:$B$65,0),MATCH('3Statement Model'!I$9,'Balance Sheet'!$D$6:$I$6,0)) -> 235 | J53: =I53 -> 235 | K53: =J53 -> 235 | L53: =K53 -> 235 | M53: =L53 -> 235 | N53: =M53 -> 235 | O53: =N53 -> 235 | P53: =O53 -> 235 | Q53: =P53 -> 235 | ... S53: =R53 -> 235 | U53: =_xlfn.RRI(5,I53,N53) -> 0 | V53: =_xlfn.RRI(3,I53,L53) -> 0
B54: Other Equity | D54: =INDEX('Balance Sheet'!$D$9:$I$65,MATCH('3Statement Model'!$B54,'Balance Sheet'!$B$9:$B$65,0),MATCH('3Statement Model'!D$9,'Balance Sheet'!$D$6:$I$6,0)) -> 8013 | E54: =INDEX('Balance Sheet'!$D$9:$I$65,MATCH('3Statement Model'!$B54,'Balance Sheet'!$B$9:$B$65,0),MATCH('3Statement Model'!E$9,'Balance Sheet'!$D$6:$I$6,0)) -> 47439 | F54: =INDEX('Balance Sheet'!$D$9:$I$65,MATCH('3Statement Model'!$B54,'Balance Sheet'!$B$9:$B$65,0),MATCH('3Statement Model'!F$9,'Balance Sheet'!$D$6:$I$6,0)) -> 48826 | G54: =INDEX('Balance Sheet'!$D$9:$I$65,MATCH('3Statement Model'!$B54,'Balance Sheet'!$B$9:$B$65,0),MATCH('3Statement Model'!G$9,'Balance Sheet'!$D$6:$I$6,0)) -> 50069 | H54: =INDEX('Balance Sheet'!$D$9:$I$65,MATCH('3Statement Model'!$B54,'Balance Sheet'!$B$9:$B$65,0),MATCH('3Statement Model'!H$9,'Balance Sheet'!$D$6:$I$6,0)) -> 50983 | I54: =INDEX('Balance Sheet'!$D$9:$I$65,MATCH('3Statement Model'!$B54,'Balance Sheet'!$B$9:$B$65,0),MATCH('3Statement Model'!I$9,'Balance Sheet'!$D$6:$I$6,0)) -> 49167 | J54: =Schedules!K209 -> 50216.981 | K54: =Schedules!L209 -> 51132.966 | L54: =Schedules!M209 -> 51883.199 | M54: =Schedules!N209 -> 52430.16 | N54: =Schedules!O209 -> 52729.635 | O54: =Schedules!P209 -> 52729.635 | P54: =Schedules!Q209 -> 52377.113 | Q54: =Schedules!R209 -> 51616 | ... S54: =Schedules!T209 -> 48639.973 | U54: =_xlfn.RRI(5,I54,N54) -> 0.014089324 | V54: =_xlfn.RRI(3,I54,L54) -> 0.018085717
B55: Total Share Holder's Equity | D55: =INDEX('Balance Sheet'!$D$9:$I$65,MATCH('3Statement Model'!$B55,'Balance Sheet'!$B$9:$B$65,0),MATCH('3Statement Model'!D$9,'Balance Sheet'!$D$6:$I$6,0)) -> 8229 | E55: =INDEX('Balance Sheet'!$D$9:$I$65,MATCH('3Statement Model'!$B55,'Balance Sheet'!$B$9:$B$65,0),MATCH('3Statement Model'!E$9,'Balance Sheet'!$D$6:$I$6,0)) -> 47674 | F55: =INDEX('Balance Sheet'!$D$9:$I$65,MATCH('3Statement Model'!$B55,'Balance Sheet'!$B$9:$B$65,0),MATCH('3Statement Model'!F$9,'Balance Sheet'!$D$6:$I$6,0)) -> 49061 | G55: =INDEX('Balance Sheet'!$D$9:$I$65,MATCH('3Statement Model'!$B55,'Balance Sheet'!$B$9:$B$65,0),MATCH('3Statement Model'!G$9,'Balance Sheet'!$D$6:$I$6,0)) -> 50304 | H55: =INDEX('Balance Sheet'!$D$9:$I$65,MATCH('3Statement Model'!$B55,'Balance Sheet'!$B$9:$B$65,0),MATCH('3Statement Model'!H$9,'Balance Sheet'!$D$6:$I$6,0)) -> 51218 | I55: =INDEX('Balance Sheet'!$D$9:$I$65,MATCH('3Statement Model'!$B55,'Balance Sheet'!$B$9:$B$65,0),MATCH('3Statement Model'!I$9,'Balance Sheet'!$D$6:$I$6,0)) -> 49402 | J55: =SUM(J53:J54) -> 50451.981 | K55: =SUM(K53:K54) -> 51367.966 | L55: =SUM(L53:L54) -> 52118.199 | M55: =SUM(M53:M54) -> 52665.16 | N55: =SUM(N53:N54) -> 52964.635 | O55: =SUM(O53:O54) -> 52964.635 | P55: =SUM(P53:P54) -> 52612.113 | Q55: =SUM(Q53:Q54) -> 51851 | ... S55: =SUM(S53:S54) -> 48874.973 | U55: =_xlfn.RRI(5,I55,N55) -> 0.014024131 | V55: =_xlfn.RRI(3,I55,L55) -> 0.018001197
B56: Minority Interest | D56: =INDEX('Balance Sheet'!$D$9:$I$65,MATCH('3Statement Model'!$B56,'Balance Sheet'!$B$9:$B$65,0),MATCH('3Statement Model'!D$9,'Balance Sheet'!$D$6:$I$6,0)) -> 17 | E56: =INDEX('Balance Sheet'!$D$9:$I$65,MATCH('3Statement Model'!$B56,'Balance Sheet'!$B$9:$B$65,0),MATCH('3Statement Model'!E$9,'Balance Sheet'!$D$6:$I$6,0)) -> 20 | F56: =INDEX('Balance Sheet'!$D$9:$I$65,MATCH('3Statement Model'!$B56,'Balance Sheet'!$B$9:$B$65,0),MATCH('3Statement Model'!F$9,'Balance Sheet'!$D$6:$I$6,0)) -> 26 | G56: =INDEX('Balance Sheet'!$D$9:$I$65,MATCH('3Statement Model'!$B56,'Balance Sheet'!$B$9:$B$65,0),MATCH('3Statement Model'!G$9,'Balance Sheet'!$D$6:$I$6,0)) -> 218 | H56: =INDEX('Balance Sheet'!$D$9:$I$65,MATCH('3Statement Model'!$B56,'Balance Sheet'!$B$9:$B$65,0),MATCH('3Statement Model'!H$9,'Balance Sheet'!$D$6:$I$6,0)) -> 205 | I56: =INDEX('Balance Sheet'!$D$9:$I$65,MATCH('3Statement Model'!$B56,'Balance Sheet'!$B$9:$B$65,0),MATCH('3Statement Model'!I$9,'Balance Sheet'!$D$6:$I$6,0)) -> 207 | J56: =I56 -> 207 | K56: =J56 -> 207 | L56: =K56 -> 207 | M56: =L56 -> 207 | N56: =M56 -> 207 | O56: =N56 -> 207 | P56: =O56 -> 207 | Q56: =P56 -> 207 | ... S56: =R56 -> 207 | U56: =_xlfn.RRI(5,I56,N56) -> 0 | V56: =_xlfn.RRI(3,I56,L56) -> 0
B57: Total Equity | D57: =INDEX('Balance Sheet'!$D$9:$I$65,MATCH('3Statement Model'!$B57,'Balance Sheet'!$B$9:$B$65,0),MATCH('3Statement Model'!D$9,'Balance Sheet'!$D$6:$I$6,0)) -> 8246 | E57: =INDEX('Balance Sheet'!$D$9:$I$65,MATCH('3Statement Model'!$B57,'Balance Sheet'!$B$9:$B$65,0),MATCH('3Statement Model'!E$9,'Balance Sheet'!$D$6:$I$6,0)) -> 47694 | F57: =INDEX('Balance Sheet'!$D$9:$I$65,MATCH('3Statement Model'!$B57,'Balance Sheet'!$B$9:$B$65,0),MATCH('3Statement Model'!F$9,'Balance Sheet'!$D$6:$I$6,0)) -> 49087 | G57: =INDEX('Balance Sheet'!$D$9:$I$65,MATCH('3Statement Model'!$B57,'Balance Sheet'!$B$9:$B$65,0),MATCH('3Statement Model'!G$9,'Balance Sheet'!$D$6:$I$6,0)) -> 50522 | H57: =INDEX('Balance Sheet'!$D$9:$I$65,MATCH('3Statement Model'!$B57,'Balance Sheet'!$B$9:$B$65,0),MATCH('3Statement Model'!H$9,'Balance Sheet'!$D$6:$I$6,0)) -> 51423 | I57: =INDEX('Balance Sheet'!$D$9:$I$65,MATCH('3Statement Model'!$B57,'Balance Sheet'!$B$9:$B$65,0),MATCH('3Statement Model'!I$9,'Balance Sheet'!$D$6:$I$6,0)) -> 49609 | J57: =SUM(J55:J56) -> 50658.981 | K57: =SUM(K55:K56) -> 51574.966 | L57: =SUM(L55:L56) -> 52325.199 | M57: =SUM(M55:M56) -> 52872.16 | N57: =SUM(N55:N56) -> 53171.635 | O57: =SUM(O55:O56) -> 53171.635 | P57: =SUM(P55:P56) -> 52819.113 | Q57: =SUM(Q55:Q56) -> 52058 | ... S57: =SUM(S55:S56) -> 49081.973
...

Sheet CommonSize Statement
B2: ='Input Sheet'!C6 -> Hindustan Unilever Ltd.
B3: 3 Statement Model
I4: Current Case:
D8: Actual | J8: Explicit Forecast Period | O8: Maturity Period
B9: In Crs Unless Stated Otherwise | D9: 2020 | E9: =D9+1 -> 2021 | F9: =E9+1 -> 2022 | G9: =F9+1 -> 2023 | H9: =G9+1 -> 2024 | I9: =H9+1 -> 2025 | J9: =I9+1 -> 2026 | K9: =J9+1 -> 2027 | L9: =K9+1 -> 2028 | ... S9: =R9+1 -> 2035
A11: # | B11: Income Statement
B13: Revenue From Operations | D13: ='3Statement Model'!D13/'3Statement Model'!D$13 -> 1 | E13: ='3Statement Model'!E13/'3Statement Model'!E$13 -> 1 | F13: ='3Statement Model'!F13/'3Statement Model'!F$13 -> 1 | G13: ='3Statement Model'!G13/'3Statement Model'!G$13 -> 1 | H13: ='3Statement Model'!H13/'3Statement Model'!H$13 -> 1 | I13: ='3Statement Model'!I13/'3Statement Model'!I$13 -> 1 | J13: ='3Statement Model'!J13/'3Statement Model'!J$13 -> 1 | K13: ='3Statement Model'!K13/'3Statement Model'!K$13 -> 1 | ... S13: ='3Statement Model'!S13/'3Statement Model'!S$13 -> 1
B14: Less: Cost of Goods Sold | D14: ='3Statement Model'!D14/'3Statement Model'!D$13 -> -0.45896488 | E14: ='3Statement Model'!E14/'3Statement Model'!E$13 -> -0.47095347 | F14: ='3Statement Model'!F14/'3Statement Model'!F$13 -> -0.49069519 | G14: ='3Statement Model'!G14/'3Statement Model'!G$13 -> -0.52345271 | H14: ='3Statement Model'!H14/'3Statement Model'!H$13 -> -0.48127304 | I14: ='3Statement Model'!I14/'3Statement Model'!I$13 -> -0.48443466 | J14: ='3Statement Model'!J14/'3Statement Model'!J$13 -> -0.49 | K14: ='3Statement Model'!K14/'3Statement Model'!K$13 -> -0.48775 | ... S14: ='3Statement Model'!S14/'3Statement Model'!S$13 -> -0.481
B15: Gross Profit | D15: ='3Statement Model'!D15/'3Statement Model'!D$13 -> 0.54103512 | E15: ='3Statement Model'!E15/'3Statement Model'!E$13 -> 0.52904653 | F15: ='3Statement Model'!F15/'3Statement Model'!F$13 -> 0.50930481 | G15: ='3Statement Model'!G15/'3Statement Model'!G$13 -> 0.47654729 | H15: ='3Statement Model'!H15/'3Statement Model'!H$13 -> 0.51872696 | I15: ='3Statement Model'!I15/'3Statement Model'!I$13 -> 0.51556534 | J15: ='3Statement Model'!J15/'3Statement Model'!J$13 -> 0.51 | K15: ='3Statement Model'!K15/'3Statement Model'!K$13 -> 0.51225 | ... S15: ='3Statement Model'!S15/'3Statement Model'!S$13 -> 0.519
B17: Less: SG&A (Excluding Depriciation & Interest)
B18: Employee Benefit Expenses | D18: ='3Statement Model'!D18/'3Statement Model'!D$13 -> -0.045748184 | E18: ='3Statement Model'!E18/'3Statement Model'!E$13 -> -0.050140342 | F18: ='3Statement Model'!F18/'3Statement Model'!F$13 -> -0.048526103 | G18: ='3Statement Model'!G18/'3Statement Model'!G$13 -> -0.047103482 | H18: ='3Statement Model'!H18/'3Statement Model'!H$13 -> -0.048660974 | I18: ='3Statement Model'!I18/'3Statement Model'!I$13 -> -0.048747643 | J18: ='3Statement Model'!J18/'3Statement Model'!J$13 -> -0.048 | K18: ='3Statement Model'!K18/'3Statement Model'!K$13 -> -0.048 | ... S18: ='3Statement Model'!S18/'3Statement Model'!S$13 -> -0.048
B19: Othere Expenses | D19: ='3Statement Model'!D19/'3Statement Model'!D$13 -> -0.24741724 | E19: ='3Statement Model'!E19/'3Statement Model'!E$13 -> -0.23169176 | F19: ='3Statement Model'!F19/'3Statement Model'!F$13 -> -0.21563132 | G19: ='3Statement Model'!G19/'3Statement Model'!G$13 -> -0.19575838 | H19: ='3Statement Model'!H19/'3Statement Model'!H$13 -> -0.23390905 | I19: ='3Statement Model'!I19/'3Statement Model'!I$13 -> -0.23153942 | J19: ='3Statement Model'!J19/'3Statement Model'!J$13 -> -0.232 | K19: ='3Statement Model'!K19/'3Statement Model'!K$13 -> -0.232 | ... S19: ='3Statement Model'!S19/'3Statement Model'!S$13 -> -0.232
B20: Total SG&A | D20: ='3Statement Model'!D20/'3Statement Model'!D$13 -> -0.29316542 | E20: ='3Statement Model'!E20/'3Statement Model'!E$13 -> -0.2818321 | F20: ='3Statement Model'!F20/'3Statement Model'!F$13 -> -0.26415742 | G20: ='3Statement Model'!G20/'3Statement Model'!G$13 -> -0.24286186 | H20: ='3Statement Model'!H20/'3Statement Model'!H$13 -> -0.28257002 | I20: ='3Statement Model'!I20/'3Statement Model'!I$13 -> -0.28028707 | J20: ='3Statement Model'!J20/'3Statement Model'!J$13 -> -0.28 | K20: ='3Statement Model'!K20/'3Statement Model'!K$13 -> -0.28 | ... S20: ='3Statement Model'!S20/'3Statement Model'!S$13 -> -0.28
B22: EBITDA | D22: ='3Statement Model'!D22/'3Statement Model'!D$13 -> 0.24786969 | E22: ='3Statement Model'!E22/'3Statement Model'!E$13 -> 0.24721443 | F22: ='3Statement Model'!F22/'3Statement Model'!F$13 -> 0.24514739 | G22: ='3Statement Model'!G22/'3Statement Model'!G$13 -> 0.23368543 | H22: ='3Statement Model'!H22/'3Statement Model'!H$13 -> 0.23615693 | I22: ='3Statement Model'!I22/'3Statement Model'!I$13 -> 0.23527828 | J22: ='3Statement Model'!J22/'3Statement Model'!J$13 -> 0.23 | K22: ='3Statement Model'!K22/'3Statement Model'!K$13 -> 0.23225 | ... S22: ='3Statement Model'!S22/'3Statement Model'!S$13 -> 0.239
B25: Less: Depreciation & Amortization | D25: ='3Statement Model'!D27/'3Statement Model'!D$13 -> -0.025186638 | E25: ='3Statement Model'!E27/'3Statement Model'!E$13 -> -0.022837459 | F25: ='3Statement Model'!F27/'3Statement Model'!F$13 -> -0.020802349 | G25: ='3Statement Model'!G27/'3Statement Model'!G$13 -> -0.018765473 | H25: ='3Statement Model'!H27/'3Statement Model'!H$13 -> -0.01966492 | I25: ='3Statement Model'!I27/'3Statement Model'!I$13 -> -0.021466707 | J25: ='3Statement Model'!J27/'3Statement Model'!J$13 -> -0.022312298 | K25: ='3Statement Model'!K27/'3Statement Model'!K$13 -> -0.022835597 | ... S25: ='3Statement Model'!S27/'3Statement Model'!S$13 -> -0.026116026
B26: Earnings Before Interest & Tax | D26: ='3Statement Model'!D28/'3Statement Model'!D$13 -> 0.22268306 | E26: ='3Statement Model'!E28/'3Statement Model'!E$13 -> 0.22437697 | F26: ='3Statement Model'!F28/'3Statement Model'!F$13 -> 0.22434504 | G26: ='3Statement Model'!G28/'3Statement Model'!G$13 -> 0.21491995 | H26: ='3Statement Model'!H28/'3Statement Model'!H$13 -> 0.21649201 | I26: ='3Statement Model'!I28/'3Statement Model'!I$13 -> 0.21381157 | J26: ='3Statement Model'!J28/'3Statement Model'!J$13 -> 0.2076877 | K26: ='3Statement Model'!K28/'3Statement Model'!K$13 -> 0.2094144 | ... S26: ='3Statement Model'!S28/'3Statement Model'!S$13 -> 0.21288397
B28: Less: Finance Costs | D28: ='3Statement Model'!D32/'3Statement Model'!D$13 -> -0.002966091 | E28: ='3Statement Model'!E32/'3Statement Model'!E$13 -> -0.0024878796 | F28: ='3Statement Model'!F32/'3Statement Model'!F$13 -> -0.0020211265 | G28: ='3Statement Model'!G32/'3Statement Model'!G$13 -> -0.0018814986 | H28: ='3Statement Model'!H32/'3Statement Model'!H$13 -> -0.0054013843 | I28: ='3Statement Model'!I32/'3Statement Model'!I$13 -> -0.0062578223 | J28: ='3Statement Model'!J32/'3Statement Model'!J$13 -> -0.0038892266 | K28: ='3Statement Model'!K32/'3Statement Model'!K$13 -> -0.0038892266 | ... S28: ='3Statement Model'!S32/'3Statement Model'!S$13 -> -0.0038892266
B29: Add: Other Income | D29: ='3Statement Model'!D33/'3Statement Model'!D$13 -> 0.015886183 | E29: ='3Statement Model'!E33/'3Statement Model'!E$13 -> 0.0087182104 | F29: ='3Statement Model'!F33/'3Statement Model'!F$13 -> 0.0049193456 | G29: ='3Statement Model'!G33/'3Statement Model'!G$13 -> 0.0084502393 | H29: ='3Statement Model'!H33/'3Statement Model'!H$13 -> 0.013115337 | I29: ='3Statement Model'!I33/'3Statement Model'!I$13 -> 0.016111912 | J29: ='3Statement Model'!J33/'3Statement Model'!J$13 -> 0.014822787 | K29: ='3Statement Model'!K33/'3Statement Model'!K$13 -> 0.013625864 | ... S29: ='3Statement Model'!S33/'3Statement Model'!S$13 -> 0.0070331537
B30: Add/(Less): Share Of Profit/Loss Of Associates | D30: ='3Statement Model'!D34/'3Statement Model'!D$13 -> 0 | E30: ='3Statement Model'!E34/'3Statement Model'!E$13 -> 0 | F30: ='3Statement Model'!F34/'3Statement Model'!F$13 -> 0 | G30: ='3Statement Model'!G34/'3Statement Model'!G$13 -> -1.6504374e-05 | H30: ='3Statement Model'!H34/'3Statement Model'!H$13 -> -6.4687237e-05 | I30: ='3Statement Model'!I34/'3Statement Model'!I$13 -> -0.0001267407 | J30: ='3Statement Model'!J34/'3Statement Model'!J$13 -> 0 | K30: ='3Statement Model'!K34/'3Statement Model'!K$13 -> 0 | ... S30: ='3Statement Model'!S34/'3Statement Model'!S$13 -> 0
B31: Add/(Less): Exceptional Items | D31: ='3Statement Model'!D35/'3Statement Model'!D$13 -> -0.005027273 | E31: ='3Statement Model'!E35/'3Statement Model'!E$13 -> -0.0050820788 | F31: ='3Statement Model'!F35/'3Statement Model'!F$13 -> -0.00083895817 | G31: ='3Statement Model'!G35/'3Statement Model'!G$13 -> -0.0010562799 | H31: ='3Statement Model'!H35/'3Statement Model'!H$13 -> 9.7030856e-05 | I31: ='3Statement Model'!I35/'3Statement Model'!I$13 -> 0.0048319894 | J31: ='3Statement Model'!J35/'3Statement Model'!J$13 -> 0 | K31: ='3Statement Model'!K35/'3Statement Model'!K$13 -> 0 | ... S31: ='3Statement Model'!S35/'3Statement Model'!S$13 -> 0
B33: Earnings Before Tax | D33: ='3Statement Model'!D37/'3Statement Model'!D$13 -> 0.23057587 | E33: ='3Statement Model'!E37/'3Statement Model'!E$13 -> 0.22552522 | F33: ='3Statement Model'!F37/'3Statement Model'!F$13 -> 0.2264043 | G33: ='3Statement Model'!G37/'3Statement Model'!G$13 -> 0.22041591 | H33: ='3Statement Model'!H37/'3Statement Model'!H$13 -> 0.22423831 | I33: ='3Statement Model'!I37/'3Statement Model'!I$13 -> 0.22837091 | J33: ='3Statement Model'!J37/'3Statement Model'!J$13 -> 0.21862126 | K33: ='3Statement Model'!K37/'3Statement Model'!K$13 -> 0.21915104 | ... S33: ='3Statement Model'!S37/'3Statement Model'!S$13 -> 0.2160279
B35: Less: Tax Expenses | D35: ='3Statement Model'!D39/'3Statement Model'!D$13 -> -0.060553503 | E35: ='3Statement Model'!E39/'3Statement Model'!E$13 -> -0.055413796 | F35: ='3Statement Model'!F39/'3Statement Model'!F$13 -> -0.056953819 | G35: ='3Statement Model'!G39/'3Statement Model'!G$13 -> -0.0528305 | H35: ='3Statement Model'!H39/'3Statement Model'!H$13 -> -0.058930073 | I35: ='3Statement Model'!I39/'3Statement Model'!I$13 -> -0.05931465 | J35: ='3Statement Model'!J39/'3Statement Model'!J$13 -> -0.065586379 | K35: ='3Statement Model'!K39/'3Statement Model'!K$13 -> -0.065745312 | ... S35: ='3Statement Model'!S39/'3Statement Model'!S$13 -> -0.06480837
B36: Net Income | D36: ='3Statement Model'!D40/'3Statement Model'!D$13 -> 0.17002237 | E36: ='3Statement Model'!E40/'3Statement Model'!E$13 -> 0.17011142 | F36: ='3Statement Model'!F40/'3Statement Model'!F$13 -> 0.16945048 | G36: ='3Statement Model'!G40/'3Statement Model'!G$13 -> 0.16758541 | H36: ='3Statement Model'!H40/'3Statement Model'!H$13 -> 0.16530823 | I36: ='3Statement Model'!I40/'3Statement Model'!I$13 -> 0.16905626 | J36: ='3Statement Model'!J40/'3Statement Model'!J$13 -> 0.15303488 | K36: ='3Statement Model'!K40/'3Statement Model'!K$13 -> 0.15340573 | ... S36: ='3Statement Model'!S40/'3Statement Model'!S$13 -> 0.15121953
A38: # | B38: Balance Sheet
B40: EQUITIES AND LIABILITIES
B41: SHAREHOLDER'S FUNDS
B42: Equity Share Capital | D42: ='3Statement Model'!D53/'3Statement Model'!D$79 -> 0.010718007 | E42: ='3Statement Model'!E53/'3Statement Model'!E$79 -> 0.0034178338 | F42: ='3Statement Model'!F53/'3Statement Model'!F$79 -> 0.0033325297 | G42: ='3Statement Model'!G53/'3Statement Model'!G$79 -> 0.0032153461 | H42: ='3Statement Model'!H53/'3Statement Model'!H$79 -> 0.0029936687 | I42: ='3Statement Model'!I53/'3Statement Model'!I$79 -> 0.0029419129 | J42: ='3Statement Model'!J53/'3Statement Model'!J$79 -> 0.0027724533 | K42: ='3Statement Model'!K53/'3Statement Model'!K$79 -> 0.0026986618 | ... S42: ='3Statement Model'!S53/'3Statement Model'!S$79 -> 0.0023217446
B43: Other Equity | D43: ='3Statement Model'!D54/'3Statement Model'!D$79 -> 0.3976083 | E43: ='3Statement Model'!E54/'3Statement Model'!E$79 -> 0.68995157 | F43: ='3Statement Model'!F54/'3Statement Model'!F$79 -> 0.69240041 | G43: ='3Statement Model'!G54/'3Statement Model'!G$79 -> 0.68506027 | H43: ='3Statement Model'!H54/'3Statement Model'!H$79 -> 0.64947324 | I43: ='3Statement Model'!I54/'3Statement Model'!I$79 -> 0.61551077 | J43: ='3Statement Model'!J54/'3Statement Model'!J$79 -> 0.59244354 | K43: ='3Statement Model'!K54/'3Statement Model'!K$79 -> 0.58719398 | ... S43: ='3Statement Model'!S54/'3Statement Model'!S$79 -> 0.48055147
B44: Total Share Holder's Equity | D44: ='3Statement Model'!D55/'3Statement Model'!D$79 -> 0.4083263 | E44: ='3Statement Model'!E55/'3Statement Model'!E$79 -> 0.6933694 | F44: ='3Statement Model'!F55/'3Statement Model'!F$79 -> 0.69573294 | G44: ='3Statement Model'!G55/'3Statement Model'!G$79 -> 0.68827562 | H44: ='3Statement Model'!H55/'3Statement Model'!H$79 -> 0.65246691 | I44: ='3Statement Model'!I55/'3Statement Model'!I$79 -> 0.61845268 | J44: ='3Statement Model'!J55/'3Statement Model'!J$79 -> 0.595216 | K44: ='3Statement Model'!K55/'3Statement Model'!K$79 -> 0.58989264 | ... S44: ='3Statement Model'!S55/'3Statement Model'!S$79 -> 0.48287322
